<?xml version="1.0" encoding="UTF-8"?>
<testng-results ignored="4" total="5" passed="0" failed="1" skipped="0">
  <reporter-output>
  </reporter-output>
  <suite started-at="2023-02-13T20:54:43 EST" name="Suite" finished-at="2023-02-13T20:54:52 EST" duration-ms="8976">
    <groups>
      <group name="Smoke">
        <method signature="LandingPageTest.testHeaders()[pri:0, instance:tests.LandingPageTest@313ac989]" name="testHeaders" class="tests.LandingPageTest"/>
      </group> <!-- Smoke -->
    </groups>
    <test started-at="2023-02-13T20:54:43 EST" name="Test" finished-at="2023-02-13T20:54:52 EST" duration-ms="8976">
      <class name="tests.LandingPageTest">
        <test-method is-config="true" signature="initializeTwo()[pri:0, instance:tests.LandingPageTest@313ac989]" started-at="2023-02-13T20:54:43 EST" name="initializeTwo" finished-at="2023-02-13T20:54:50 EST" duration-ms="6964" status="PASS">
          <reporter-output>
          </reporter-output>
        </test-method> <!-- initializeTwo -->
        <test-method signature="testHeaders()[pri:0, instance:tests.LandingPageTest@313ac989]" started-at="2023-02-13T20:54:50 EST" name="testHeaders" finished-at="2023-02-13T20:54:51 EST" duration-ms="1215" status="FAIL">
          <exception class="java.lang.AssertionError">
            <message>
              <![CDATA[expected [true] but found [false]]]>
            </message>
            <full-stacktrace>
              <![CDATA[java.lang.AssertionError: expected [true] but found [false]
at org.testng.Assert.fail(Assert.java:110)
at org.testng.Assert.failNotEquals(Assert.java:1577)
at org.testng.Assert.assertTrue(Assert.java:56)
at org.testng.Assert.assertTrue(Assert.java:66)
at tests.LandingPageTest.testHeaders(LandingPageTest.java:69)
at java.base/jdk.internal.reflect.DirectMethodHandleAccessor.invoke(DirectMethodHandleAccessor.java:104)
at java.base/java.lang.reflect.Method.invoke(Method.java:577)
at org.testng.internal.invokers.MethodInvocationHelper.invokeMethod(MethodInvocationHelper.java:139)
at org.testng.internal.invokers.TestInvoker.invokeMethod(TestInvoker.java:677)
at org.testng.internal.invokers.TestInvoker.invokeTestMethod(TestInvoker.java:221)
at org.testng.internal.invokers.MethodRunner.runInSequence(MethodRunner.java:50)
at org.testng.internal.invokers.TestInvoker$MethodInvocationAgent.invoke(TestInvoker.java:969)
at org.testng.internal.invokers.TestInvoker.invokeTestMethods(TestInvoker.java:194)
at org.testng.internal.invokers.TestMethodWorker.invokeTestMethods(TestMethodWorker.java:148)
at org.testng.internal.invokers.TestMethodWorker.run(TestMethodWorker.java:128)
at java.base/java.util.ArrayList.forEach(ArrayList.java:1511)
at org.testng.TestRunner.privateRun(TestRunner.java:829)
at org.testng.TestRunner.run(TestRunner.java:602)
at org.testng.SuiteRunner.runTest(SuiteRunner.java:437)
at org.testng.SuiteRunner$SuiteWorker.run(SuiteRunner.java:475)
at org.testng.internal.thread.ThreadUtil.lambda$execute$0(ThreadUtil.java:58)
at java.base/java.util.concurrent.FutureTask.run(FutureTask.java:264)
at java.base/java.util.concurrent.ThreadPoolExecutor.runWorker(ThreadPoolExecutor.java:1136)
at java.base/java.util.concurrent.ThreadPoolExecutor$Worker.run(ThreadPoolExecutor.java:635)
at java.base/java.lang.Thread.run(Thread.java:833)
]]>
            </full-stacktrace>
          </exception> <!-- java.lang.AssertionError -->
          <reporter-output>
          </reporter-output>
        </test-method> <!-- testHeaders -->
        <test-method is-config="true" signature="tearDownTwo()[pri:0, instance:tests.LandingPageTest@313ac989]" started-at="2023-02-13T20:54:52 EST" name="tearDownTwo" finished-at="2023-02-13T20:54:52 EST" duration-ms="77" status="PASS">
          <reporter-output>
          </reporter-output>
        </test-method> <!-- tearDownTwo -->
      </class> <!-- tests.LandingPageTest -->
    </test> <!-- Test -->
  </suite> <!-- Suite -->
</testng-results>
